[2020-11-08 16:13:26,349] [autoreload.py:578] [autoreload:run_with_reloader] [INFO]- Watching for file changes with StatReloader
[2020-11-08 16:13:45,666] [basehttp.py:154] [basehttp:log_message] [INFO]- "GET / HTTP/1.1" 200 2
[2020-11-08 16:14:38,553] [autoreload.py:203] [autoreload:trigger_reload] [INFO]- G:\新知识\python\celery_test\App\views.py changed, reloading.
[2020-11-08 16:14:39,960] [autoreload.py:578] [autoreload:run_with_reloader] [INFO]- Watching for file changes with StatReloader
[2020-11-08 16:33:31,958] [autoreload.py:203] [autoreload:trigger_reload] [INFO]- G:\新知识\python\celery_test\celery_test\settings.py changed, reloading.
[2020-11-08 16:35:15,444] [autoreload.py:578] [autoreload:run_with_reloader] [INFO]- Watching for file changes with StatReloader
[2020-11-08 16:35:22,748] [basehttp.py:154] [basehttp:log_message] [ERROR]- "GET / HTTP/1.1" 500 27
[2020-11-08 16:41:31,194] [autoreload.py:578] [autoreload:run_with_reloader] [INFO]- Watching for file changes with StatReloader
[2020-11-08 16:41:35,830] [log.py:222] [log:log_response] [ERROR]- Internal Server Error: /
Traceback (most recent call last):
  File "E:\Anaconda3\envs\celery\lib\site-packages\django\core\handlers\exception.py", line 34, in inner
    response = get_response(request)
  File "E:\Anaconda3\envs\celery\lib\site-packages\django\core\handlers\base.py", line 115, in _get_response
    response = self.process_exception_by_middleware(e, request)
  File "E:\Anaconda3\envs\celery\lib\site-packages\django\core\handlers\base.py", line 113, in _get_response
    response = wrapped_callback(request, *callback_args, **callback_kwargs)
  File "G:\新知识\python\celery_test\App\views.py", line 13, in index
    print(1 / 0)
ZeroDivisionError: division by zero
[2020-11-08 16:41:46,933] [basehttp.py:154] [basehttp:log_message] [ERROR]- "GET / HTTP/1.1" 500 27
[2020-11-08 16:44:09,194] [autoreload.py:578] [autoreload:run_with_reloader] [INFO]- Watching for file changes with StatReloader
[2020-11-08 16:44:13,898] [log.py:222] [log:log_response] [ERROR]- Internal Server Error: /
Traceback (most recent call last):
  File "E:\Anaconda3\envs\celery\lib\site-packages\django\core\handlers\exception.py", line 34, in inner
    response = get_response(request)
  File "E:\Anaconda3\envs\celery\lib\site-packages\django\core\handlers\base.py", line 115, in _get_response
    response = self.process_exception_by_middleware(e, request)
  File "E:\Anaconda3\envs\celery\lib\site-packages\django\core\handlers\base.py", line 113, in _get_response
    response = wrapped_callback(request, *callback_args, **callback_kwargs)
  File "G:\新知识\python\celery_test\App\views.py", line 13, in index
    print(1 / 0)
ZeroDivisionError: division by zero
[2020-11-08 16:44:24,993] [basehttp.py:154] [basehttp:log_message] [ERROR]- "GET / HTTP/1.1" 500 27
