[2020-11-09 09:37:40,586] [log.py:222] [log:log_response] [ERROR]- Internal Server Error: /cbv
Traceback (most recent call last):
  File "E:\Anaconda3\envs\celery\lib\site-packages\django\core\handlers\exception.py", line 34, in inner
    response = get_response(request)
  File "E:\Anaconda3\envs\celery\lib\site-packages\django\core\handlers\base.py", line 115, in _get_response
    response = self.process_exception_by_middleware(e, request)
  File "E:\Anaconda3\envs\celery\lib\site-packages\django\core\handlers\base.py", line 113, in _get_response
    response = wrapped_callback(request, *callback_args, **callback_kwargs)
  File "E:\Anaconda3\envs\celery\lib\site-packages\django\views\generic\base.py", line 71, in view
    return self.dispatch(request, *args, **kwargs)
  File "E:\Anaconda3\envs\celery\lib\site-packages\django\views\generic\base.py", line 97, in dispatch
    return handler(request, *args, **kwargs)
TypeError: get() takes 1 positional argument but 2 were given
